<?xml version="1.0"?>
<robot name="differential_robot" xmlns:xacro="http://www.ros.org/wiki/xacro">

    <!-- Chassis link -->
    <link name="chassis">
        <inertial>
            <mass value="1.0" />
            <inertia ixx="0.1" ixy="0.0" ixz="0.0" iyy="0.1" iyz="0.0" izz="0.1" />
        </inertial>
        <collision>
            <origin xyz="0 0 0" rpy="0 0 0" />
            <geometry>
                <box size="0.5 0.5 0.1" />
            </geometry>
        </collision>
        <visual>
            <origin xyz="0 0 0" rpy="0 0 0" />
            <geometry>
                <box size="0.5 0.5 0.1" />
            </geometry>
        </visual>
    </link>

    <!-- Left wheel link -->
    <link name="left_wheel">
        <collision>
            <origin xyz="0 0 0" rpy="0 0 0" />
            <geometry>
                <cylinder radius="0.05" length="0.1" />
            </geometry>
        </collision>
        <visual>
            <origin xyz="0 0 0" rpy="0 0 0" />
            <geometry>
                <cylinder radius="0.05" length="0.1" />
            </geometry>
        </visual>
        <inertial>
            <mass value="0.1" />
            <inertia ixx="0.0001" ixy="0.0" ixz="0.0" iyy="0.0001" iyz="0.0" izz="0.0001" />
        </inertial>
    </link>

    <!-- Right wheel link -->
    <link name="right_wheel">
        <collision>
            <origin xyz="0 0 0" rpy="0 0 0" />
            <geometry>
                <cylinder radius="0.05" length="0.1" />
            </geometry>
        </collision>
        <visual>
            <origin xyz="0 0 0" rpy="0 0 0" />
            <geometry>
                <cylinder radius="0.05" length="0.1" />
            </geometry>
        </visual>
        <inertial>
            <mass value="0.1" />
            <inertia ixx="0.0001" ixy="0.0" ixz="0.0" iyy="0.0001" iyz="0.0" izz="0.0001" />
        </inertial>
    </link>

    <!-- Left wheel joint -->
    <joint name="left_wheel_joint" type="continuous">
        <parent link="chassis" />
        <child link="left_wheel" />
        <origin xyz="0.0 0.3 0.05" rpy="0 0 0" />
        <axis xyz="0 1 0" />
        <dynamics damping="0.1" />
    </joint>

    <!-- Right wheel joint -->
    <joint name="right_wheel_joint" type="continuous">
        <parent link="chassis" />
        <child link="right_wheel" />
        <origin xyz="0.0 -0.3 0.05" rpy="0 0 0" />
        <axis xyz="0 1 0" />
        <dynamics damping="0.1" />
    </joint>

    <!-- Transmission for left wheel -->
    <transmission name="left_wheel_trans">
        <type>transmission_interface/SimpleTransmission</type>
        <joint name="left_wheel_joint">
            <hardwareInterface>hardware_interface/EffortJointInterface</hardwareInterface>
        </joint>
        <actuator name="left_motor">
            <hardwareInterface>hardware_interface/EffortJointInterface</hardwareInterface>
            <mechanicalReduction>1</mechanicalReduction>
        </actuator>
    </transmission>

    <!-- Transmission for right wheel -->
    <transmission name="right_wheel_trans">
        <type>transmission_interface/SimpleTransmission</type>
        <joint name="right_wheel_joint">
            <hardwareInterface>hardware_interface/EffortJointInterface</hardwareInterface>
        </joint>
        <actuator name="right_motor">
            <hardwareInterface>hardware_interface/EffortJointInterface</hardwareInterface>
            <mechanicalReduction>1</mechanicalReduction>
        </actuator>
    </transmission>

    <!-- Plugin for Gazebo -->
    <gazebo>
        <plugin name="gazebo_ros_control" filename="libgazebo_ros_control.so">
            <robotNamespace>/</robotNamespace>
            <robotSimType>gazebo_ros_control/GazeboRosControlPlugin</robotSimType>
        </plugin>
    </gazebo>

</robot>