<?xml version="1.0"?>
<sdf version="1.6">
    <world name="default">
        <!-- Ground Plane -->
        <include>
            <uri>model://ground_plane</uri>
        </include>

        <!-- Sun -->
        <include>
            <uri>model://sun</uri>
        </include>

        <!-- Box Model with Joint -->
        <model name="box_model">
            <pose>0 0 0.5 0 0 0</pose>

            <!-- Link 1 -->
            <link name="link1">
                <pose>0 0 0 0 0 0</pose>
                <collision name="collision1">
                    <geometry>
                        <box>
                            <size>1 1 1</size>
                        </box>
                    </geometry>
                </collision>
                <visual name="visual1">
                    <geometry>
                        <box>
                            <size>1 1 1</size>
                        </box>
                    </geometry>
                </visual>
            </link>

            <!-- Link 2 -->
            <link name="link2">
                <pose>0 0 1.2 0 0 0</pose>
                <collision name="collision2">
                    <geometry>
                        <box>
                            <size>0.5 0.5 0.5</size>
                        </box>
                    </geometry>
                </collision>
                <visual name="visual2">
                    <geometry>
                        <box>
                            <size>0.5 0.5 0.5</size>
                        </box>
                    </geometry>
                </visual>
            </link>

            <!-- Joint -->
            <joint name="joint1" type="revolute">
                <parent>link1</parent>
                <child>link2</child>
                <origin xyz="0 0 1.2" />
                <axis>
                    <xyz>0 0 1</xyz>
                    <!-- <limit>
                        <lower>-1.57</lower>
                        <upper>1.57</upper>
                    </limit>
                    <dynamics>
                        <damping>0.0</damping>
                        <friction>0.0</friction>
                    </dynamics> -->
                </axis>
            </joint>

            <!-- Plugin to Control Joint -->
            <plugin name="FixedJointVelocity" filename="libFixedJointVelocity.so">
                <jointName>joint1</jointName>
                <velocity>0.5</velocity>
            </plugin>
        </model>
    </world>
</sdf>